Workbook

Sheet Risultati
A1: ⚽ CALENDARIO & RISULTATI — 5 GIORNATE / 60 PARTITE
A2: GG | B2: DATA | C2: CASA | D2: GOL | E2: — | F2: GOL | G2: TRASFERTA | H2: NOTE | I2: MVP NOME | J2: MVP SQUADRA
A3: ━━━━━━━━━━━━ GIORNATA 1 ━━━━━━━━━━━━
A4: 1 | B4: 46176 | C4: MAROCCO | D4: 5 | E4: : | F4: 1 | G4: SVIZZERA | H4: 20:00/21:00 | I4: LUCA MASCIOLI | J4: MAROCCO
A5: 1 | B5: 46176 | C5: BRASILE | D5: 3 | E5: : | F5: 3 | G5: ARGENTINA | H5: 21:00/22:00 | I5: GABRIELE MIZZONI | J5: BRASILE
A6: 1 | B6: 46176 | C6: ECUADOR | D6: 4 | E6: : | F6: 7 | G6: MESSICO | H6: 22:00/23:00 | I6: CHRISTIAN FERRANTE | J6: MESSICO
A7: 1 | B7: 46177 | C7: SPAGNA | D7: 5 | E7: : | F7: 5 | G7: GERMANIA | H7: 20:00/21:00 | I7: DAMIANO FRATINI | J7: GERMANIA
A8: 1 | B8: 46177 | C8: NORVEGIA | D8: 2 | E8: : | F8: 1 | G8: JAMAICA | H8: 21:00/22:00 | I8: ANTONIO PROIETTI | J8: NORVEGIA
A9: 1 | B9: 46177 | C9: COSTA D'AVORIO | D9: 5 | E9: : | F9: 3 | G9: GIAPPONE | H9: 22:00/23:00 | I9: SIMONE TANI | J9: COSTA D'AVORIO
A10: 1 | B10: 46178 | C10: OLANDA | D10: 11 | E10: : | F10: 2 | G10: ALGERIA | H10: 20:00/21:00 | I10: PIERLUIGI PAOLACCI | J10: OLANDA
A11: 1 | B11: 46178 | C11: PORTOGALLO | D11: 2 | E11: : | F11: 3 | G11: INGHILTERRA | H11: 21:00/22:00 | I11: NICOLÒ CIARAGLIA | J11: INGHILTERRA
A12: 1 | B12: 46178 | C12: ITALIA | D12: 11 | E12: : | F12: 2 | G12: URUGUAY | H12: 22:00/23:00 | I12: MICHAEL PIRO | J12: ITALIA
A13: 1 | B13: 46181 | C13: USA | D13: 3 | E13: : | F13: 2 | G13: NUOVA ZELANDA | H13: 20:00/21:00 | I13: FRANCESCO MARIANI | J13: USA
A14: 1 | B14: 46181 | C14: FRANCIA | D14: 4 | E14: : | F14: 9 | G14: QATAR | H14: 21:00/22:00 | I14: FRANCESCO CATANI | J14: QATAR
A15: 1 | B15: 46181 | C15: SCOZIA | D15: 4 | E15: : | F15: 7 | G15: COLOMBIA | H15: 22:00/23:00 | I15: ANDREA CHILORIO | J15: COLOMBIA
A16: ━━━━━━━━━━━━ GIORNATA 2 ━━━━━━━━━━━━
A17: 2 | B17: 46182 | C17: SPAGNA | D17: 3 | E17: : | F17: 3 | G17: MESSICO | H17: 20:00/21:00 | I17: FEDERICO GIULITTI | J17: SPAGNA
A18: 2 | B18: 46182 | C18: ARGENTINA | D18: 2 | E18: : | F18: 1 | G18: NORVEGIA | H18: 21:00/22:00 | I18: ROBERT BANITA | J18: ARGENTINA
A19: 2 | B19: 46182 | C19: JAMAICA | D19: 1 | E19: : | F19: 3 | G19: GIAPPONE | H19: 22:00/23:00 | I19: LUCA MANTOVANI | J19: GIAPPONE
A20: 2 | B20: 46183 | C20: COSTA D'AVORIO | D20: 10 | E20: : | F20: 5 | G20: NUOVA ZELANDA | H20: 20:00/21:00 | I20: ALESSIO VIRDIS | J20: COSTA D'AVORIO
A21: 2 | B21: 46183 | C21: INGHILTERRA | D21: 3 | E21: : | F21: 4 | G21: ALGERIA | H21: 21:00/22:00 | I21: RICCARDO CORTELLESSA | J21: ALGERIA
A22: 2 | B22: 46183 | C22: ITALIA | D22: 4 | E22: : | F22: 4 | G22: OLANDA | H22: 22:00/23:00 | I22: ERIK VASTA | J22: ITALIA
A23: 2 | B23: 46184 | C23: PORTOGALLO | D23: 4 | E23: : | F23: 2 | G23: SVIZZERA | H23: 20:00/21:00 | I23: NICHOLAS MONOPOLI | J23: PORTOGALLO
A24: 2 | B24: 46184 | C24: BRASILE | D24: 5 | E24: : | F24: 1 | G24: COLOMBIA | H24: 21:00/22:00 | I24: DENNYS SAVI | J24: BRASILE
A25: 2 | B25: 46184 | C25: MAROCCO | D25: 4 | E25: : | F25: 3 | G25: SCOZIA | H25: 22:00/23:00 | I25: ALESSANDRO MOSTACCI | J25: MAROCCO
A26: 2 | B26: 46185 | C26: USA | D26: 5 | E26: : | F26: 8 | G26: QATAR | H26: 20:00/21:00 | I26: MARCO FALASCA | J26: QATAR
A27: 2 | B27: 46185 | C27: ECUADOR | D27: 6 | E27: : | F27: 5 | G27: FRANCIA | H27: 21:00/22:00 | I27: ANDREA FERRANTE | J27: ECUADOR
A28: 2 | B28: 46185 | C28: URUGUAY | D28: 2 | E28: : | F28: 7 | G28: GERMANIA | H28: 22:00/23:00 | I28: EDOARDO DAL MONTE | J28: GERMANIA
A29: ━━━━━━━━━━━━ GIORNATA 3 ━━━━━━━━━━━━
A30: 3 | B30: 46188 | C30: MESSICO | D30: 6 | E30: : | F30: 2 | G30: INGHILTERRA | H30: 20:00/21:00 | I30: RICCARDO CIPOLLONI | J30: MESSICO
A31: 3 | B31: 46188 | C31: SPAGNA | D31: 7 | E31: : | F31: 2 | G31: GIAPPONE | H31: 21:00/22:00 | I31: FEDERICO GIULITTI | J31: SPAGNA
A32: 3 | B32: 46188 | C32: PORTOGALLO | D32: 3 | E32: : | F32: 3 | G32: ALGERIA | H32: 22:00/23:00 | I32: ALESSANDRO SANTIA | J32: ALGERIA
A33: 3 | B33: 46189 | C33: ARGENTINA | D33: 4 | E33: : | F33: 5 | G33: SCOZIA | H33: 20:00/21:00 | I33: RICHARD KOEPKE | J33: SCOZIA
A34: 3 | B34: 46189 | C34: ITALIA | D34: 2 | E34: : | F34: 2 | G34: QATAR | H34: 21:00/22:00 | I34: EDOARDO MANTOVANI | J34: QATAR
A35: 3 | B35: 46189 | C35: BRASILE | D35: 5 | E35: : | F35: 2 | G35: NORVEGIA | H35: 22:00/23:00 | I35: CRISTIANO CECCHINI | J35: BRASILE
A36: 3 | B36: 46190 | C36: USA | D36: 3 | E36: : | F36: 4 | G36: FRANCIA | H36: 20:00/21:00 | I36: GIANMARCO SCAROZZA | J36: FRANCIA
A37: 3 | B37: 46190 | C37: ECUADOR | D37: 1 | E37: : | F37: 2 | G37: COLOMBIA | H37: 21:00/22:00 | I37: LORENZO FREZZOTTI | J37: COLOMBIA
A38: 3 | B38: 46190 | C38: SVIZZERA | D38: 10 | E38: : | F38: 4 | G38: NUOVA ZELANDA | H38: 22:00/23:00 | I38: ALESSIO CARDELLINI | J38: SVIZZERA
A39: 3 | B39: 46191 | C39: COSTA D'AVORIO | D39: 10 | E39: : | F39: 1 | G39: JAMAICA | H39: 20:00/21:00 | I39: PIETRO PERA | J39: COSTA D'AVORIO
A40: 3 | B40: 46191 | C40: MAROCCO | D40: 9 | E40: : | F40: 1 | G40: GERMANIA | H40: 21:00/22:00 | I40: RIDA ECH CHOUBY | J40: MAROCCO
...

Sheet Classifica
A1: 🌍 CLASSIFICA — MONDIALE ESTATE 2026
A2: POS | B2: SQUADRA | C2: F | D2: G | E2: V | F2: N | G2: P | H2: GF | I2: GS | J2: DR | K2: PTS
A3: 1 | B3: ARGENTINA | C3: 3 | D3: =SUMPRODUCT((Risultati!$C$2:$C$200=B3)*(Risultati!$D$2:$D$200<>""))+SUMPRODUCT((Risultati!$G$2:$G$200=B3)*(Risultati!$D$2:$D$200<>"")) -> 3 | E3: =SUMPRODUCT((Risultati!$C$2:$C$200=B3)*(IFERROR(VALUE(Risultati!$D$2:$D$200),0)>IFERROR(VALUE(Risultati!$F$2:$F$200),0)))+SUMPRODUCT((Risultati!$G$2:$G$200=B3)*(IFERROR(VALUE(Risultati!$F$2:$F$200),0)>IFERROR(VALUE(Risultati!$D$2:$D$200),0))) -> 1 | F3: =SUMPRODUCT((Risultati!$C$2:$C$200=B3)*(Risultati!$D$2:$D$200<>"")*((IFERROR(VALUE(Risultati!$D$2:$D$200),0))=(IFERROR(VALUE(Risultati!$F$2:$F$200),0))))+SUMPRODUCT((Risultati!$G$2:$G$200=B3)*(Risultati!$D$2:$D$200<>"")*((IFERROR(VALUE(Risultati!$D$2:$D$200),0))=(IFERROR(VALUE(Risultati!$F$2:$F$200),0)))) -> 1 | G3: =SUMPRODUCT((Risultati!$C$2:$C$200=B3)*(Risultati!$D$2:$D$200<>"")*((IFERROR(VALUE(Risultati!$D$2:$D$200),0))<(IFERROR(VALUE(Risultati!$F$2:$F$200),0))))+SUMPRODUCT((Risultati!$G$2:$G$200=B3)*(Risultati!$D$2:$D$200<>"")*((IFERROR(VALUE(Risultati!$F$2:$F$200),0))<(IFERROR(VALUE(Risultati!$D$2:$D$200),0)))) -> 1 | H3: =SUMPRODUCT((Risultati!$C$2:$C$200=B3)*(Risultati!$D$2:$D$200<>"")*IFERROR(VALUE(Risultati!$D$2:$D$200),0))+SUMPRODUCT((Risultati!$G$2:$G$200=B3)*(Risultati!$D$2:$D$200<>"")*IFERROR(VALUE(Risultati!$F$2:$F$200),0)) -> 9 | I3: =SUMPRODUCT((Risultati!$C$2:$C$200=B3)*(Risultati!$D$2:$D$200<>"")*IFERROR(VALUE(Risultati!$F$2:$F$200),0))+SUMPRODUCT((Risultati!$G$2:$G$200=B3)*(Risultati!$D$2:$D$200<>"")*IFERROR(VALUE(Risultati!$D$2:$D$200),0)) -> 9 | J3: =H3-I3 -> 0 | K3: =E3*3+F3 -> 4
A4: 2 | B4: BRASILE | C4: 2 | D4: =SUMPRODUCT((Risultati!$C$2:$C$200=B4)*(Risultati!$D$2:$D$200<>""))+SUMPRODUCT((Risultati!$G$2:$G$200=B4)*(Risultati!$D$2:$D$200<>"")) -> 4 | E4: =SUMPRODUCT((Risultati!$C$2:$C$200=B4)*(IFERROR(VALUE(Risultati!$D$2:$D$200),0)>IFERROR(VALUE(Risultati!$F$2:$F$200),0)))+SUMPRODUCT((Risultati!$G$2:$G$200=B4)*(IFERROR(VALUE(Risultati!$F$2:$F$200),0)>IFERROR(VALUE(Risultati!$D$2:$D$200),0))) -> 2 | F4: =SUMPRODUCT((Risultati!$C$2:$C$200=B4)*(Risultati!$D$2:$D$200<>"")*((IFERROR(VALUE(Risultati!$D$2:$D$200),0))=(IFERROR(VALUE(Risultati!$F$2:$F$200),0))))+SUMPRODUCT((Risultati!$G$2:$G$200=B4)*(Risultati!$D$2:$D$200<>"")*((IFERROR(VALUE(Risultati!$D$2:$D$200),0))=(IFERROR(VALUE(Risultati!$F$2:$F$200),0)))) -> 1 | G4: =SUMPRODUCT((Risultati!$C$2:$C$200=B4)*(Risultati!$D$2:$D$200<>"")*((IFERROR(VALUE(Risultati!$D$2:$D$200),0))<(IFERROR(VALUE(Risultati!$F$2:$F$200),0))))+SUMPRODUCT((Risultati!$G$2:$G$200=B4)*(Risultati!$D$2:$D$200<>"")*((IFERROR(VALUE(Risultati!$F$2:$F$200),0))<(IFERROR(VALUE(Risultati!$D$2:$D$200),0)))) -> 1 | H4: =SUMPRODUCT((Risultati!$C$2:$C$200=B4)*(Risultati!$D$2:$D$200<>"")*IFERROR(VALUE(Risultati!$D$2:$D$200),0))+SUMPRODUCT((Risultati!$G$2:$G$200=B4)*(Risultati!$D$2:$D$200<>"")*IFERROR(VALUE(Risultati!$F$2:$F$200),0)) -> 15 | I4: =SUMPRODUCT((Risultati!$C$2:$C$200=B4)*(Risultati!$D$2:$D$200<>"")*IFERROR(VALUE(Risultati!$F$2:$F$200),0))+SUMPRODUCT((Risultati!$G$2:$G$200=B4)*(Risultati!$D$2:$D$200<>"")*IFERROR(VALUE(Risultati!$D$2:$D$200),0)) -> 11 | J4: =H4-I4 -> 4 | K4: =E4*3+F4 -> 7
A5: 3 | B5: SPAGNA | C5: 2 | D5: =SUMPRODUCT((Risultati!$C$2:$C$200=B5)*(Risultati!$D$2:$D$200<>""))+SUMPRODUCT((Risultati!$G$2:$G$200=B5)*(Risultati!$D$2:$D$200<>"")) -> 3 | E5: =SUMPRODUCT((Risultati!$C$2:$C$200=B5)*(IFERROR(VALUE(Risultati!$D$2:$D$200),0)>IFERROR(VALUE(Risultati!$F$2:$F$200),0)))+SUMPRODUCT((Risultati!$G$2:$G$200=B5)*(IFERROR(VALUE(Risultati!$F$2:$F$200),0)>IFERROR(VALUE(Risultati!$D$2:$D$200),0))) -> 1 | F5: =SUMPRODUCT((Risultati!$C$2:$C$200=B5)*(Risultati!$D$2:$D$200<>"")*((IFERROR(VALUE(Risultati!$D$2:$D$200),0))=(IFERROR(VALUE(Risultati!$F$2:$F$200),0))))+SUMPRODUCT((Risultati!$G$2:$G$200=B5)*(Risultati!$D$2:$D$200<>"")*((IFERROR(VALUE(Risultati!$D$2:$D$200),0))=(IFERROR(VALUE(Risultati!$F$2:$F$200),0)))) -> 2 | G5: =SUMPRODUCT((Risultati!$C$2:$C$200=B5)*(Risultati!$D$2:$D$200<>"")*((IFERROR(VALUE(Risultati!$D$2:$D$200),0))<(IFERROR(VALUE(Risultati!$F$2:$F$200),0))))+SUMPRODUCT((Risultati!$G$2:$G$200=B5)*(Risultati!$D$2:$D$200<>"")*((IFERROR(VALUE(Risultati!$F$2:$F$200),0))<(IFERROR(VALUE(Risultati!$D$2:$D$200),0)))) -> 0 | H5: =SUMPRODUCT((Risultati!$C$2:$C$200=B5)*(Risultati!$D$2:$D$200<>"")*IFERROR(VALUE(Risultati!$D$2:$D$200),0))+SUMPRODUCT((Risultati!$G$2:$G$200=B5)*(Risultati!$D$2:$D$200<>"")*IFERROR(VALUE(Risultati!$F$2:$F$200),0)) -> 15 | I5: =SUMPRODUCT((Risultati!$C$2:$C$200=B5)*(Risultati!$D$2:$D$200<>"")*IFERROR(VALUE(Risultati!$F$2:$F$200),0))+SUMPRODUCT((Risultati!$G$2:$G$200=B5)*(Risultati!$D$2:$D$200<>"")*IFERROR(VALUE(Risultati!$D$2:$D$200),0)) -> 10 | J5: =H5-I5 -> 5 | K5: =E5*3+F5 -> 5
A6: 4 | B6: GERMANIA | C6: 4 | D6: =SUMPRODUCT((Risultati!$C$2:$C$200=B6)*(Risultati!$D$2:$D$200<>""))+SUMPRODUCT((Risultati!$G$2:$G$200=B6)*(Risultati!$D$2:$D$200<>"")) -> 3 | E6: =SUMPRODUCT((Risultati!$C$2:$C$200=B6)*(IFERROR(VALUE(Risultati!$D$2:$D$200),0)>IFERROR(VALUE(Risultati!$F$2:$F$200),0)))+SUMPRODUCT((Risultati!$G$2:$G$200=B6)*(IFERROR(VALUE(Risultati!$F$2:$F$200),0)>IFERROR(VALUE(Risultati!$D$2:$D$200),0))) -> 1 | F6: =SUMPRODUCT((Risultati!$C$2:$C$200=B6)*(Risultati!$D$2:$D$200<>"")*((IFERROR(VALUE(Risultati!$D$2:$D$200),0))=(IFERROR(VALUE(Risultati!$F$2:$F$200),0))))+SUMPRODUCT((Risultati!$G$2:$G$200=B6)*(Risultati!$D$2:$D$200<>"")*((IFERROR(VALUE(Risultati!$D$2:$D$200),0))=(IFERROR(VALUE(Risultati!$F$2:$F$200),0)))) -> 1 | G6: =SUMPRODUCT((Risultati!$C$2:$C$200=B6)*(Risultati!$D$2:$D$200<>"")*((IFERROR(VALUE(Risultati!$D$2:$D$200),0))<(IFERROR(VALUE(Risultati!$F$2:$F$200),0))))+SUMPRODUCT((Risultati!$G$2:$G$200=B6)*(Risultati!$D$2:$D$200<>"")*((IFERROR(VALUE(Risultati!$F$2:$F$200),0))<(IFERROR(VALUE(Risultati!$D$2:$D$200),0)))) -> 1 | H6: =SUMPRODUCT((Risultati!$C$2:$C$200=B6)*(Risultati!$D$2:$D$200<>"")*IFERROR(VALUE(Risultati!$D$2:$D$200),0))+SUMPRODUCT((Risultati!$G$2:$G$200=B6)*(Risultati!$D$2:$D$200<>"")*IFERROR(VALUE(Risultati!$F$2:$F$200),0)) -> 13 | I6: =SUMPRODUCT((Risultati!$C$2:$C$200=B6)*(Risultati!$D$2:$D$200<>"")*IFERROR(VALUE(Risultati!$F$2:$F$200),0))+SUMPRODUCT((Risultati!$G$2:$G$200=B6)*(Risultati!$D$2:$D$200<>"")*IFERROR(VALUE(Risultati!$D$2:$D$200),0)) -> 16 | J6: =H6-I6 -> -3 | K6: =E6*3+F6 -> 4
A7: 5 | B7: PORTOGALLO | C7: 2 | D7: =SUMPRODUCT((Risultati!$C$2:$C$200=B7)*(Risultati!$D$2:$D$200<>""))+SUMPRODUCT((Risultati!$G$2:$G$200=B7)*(Risultati!$D$2:$D$200<>"")) -> 4 | E7: =SUMPRODUCT((Risultati!$C$2:$C$200=B7)*(IFERROR(VALUE(Risultati!$D$2:$D$200),0)>IFERROR(VALUE(Risultati!$F$2:$F$200),0)))+SUMPRODUCT((Risultati!$G$2:$G$200=B7)*(IFERROR(VALUE(Risultati!$F$2:$F$200),0)>IFERROR(VALUE(Risultati!$D$2:$D$200),0))) -> 2 | F7: =SUMPRODUCT((Risultati!$C$2:$C$200=B7)*(Risultati!$D$2:$D$200<>"")*((IFERROR(VALUE(Risultati!$D$2:$D$200),0))=(IFERROR(VALUE(Risultati!$F$2:$F$200),0))))+SUMPRODUCT((Risultati!$G$2:$G$200=B7)*(Risultati!$D$2:$D$200<>"")*((IFERROR(VALUE(Risultati!$D$2:$D$200),0))=(IFERROR(VALUE(Risultati!$F$2:$F$200),0)))) -> 1 | G7: =SUMPRODUCT((Risultati!$C$2:$C$200=B7)*(Risultati!$D$2:$D$200<>"")*((IFERROR(VALUE(Risultati!$D$2:$D$200),0))<(IFERROR(VALUE(Risultati!$F$2:$F$200),0))))+SUMPRODUCT((Risultati!$G$2:$G$200=B7)*(Risultati!$D$2:$D$200<>"")*((IFERROR(VALUE(Risultati!$F$2:$F$200),0))<(IFERROR(VALUE(Risultati!$D$2:$D$200),0)))) -> 1 | H7: =SUMPRODUCT((Risultati!$C$2:$C$200=B7)*(Risultati!$D$2:$D$200<>"")*IFERROR(VALUE(Risultati!$D$2:$D$200),0))+SUMPRODUCT((Risultati!$G$2:$G$200=B7)*(Risultati!$D$2:$D$200<>"")*IFERROR(VALUE(Risultati!$F$2:$F$200),0)) -> 16 | I7: =SUMPRODUCT((Risultati!$C$2:$C$200=B7)*(Risultati!$D$2:$D$200<>"")*IFERROR(VALUE(Risultati!$F$2:$F$200),0))+SUMPRODUCT((Risultati!$G$2:$G$200=B7)*(Risultati!$D$2:$D$200<>"")*IFERROR(VALUE(Risultati!$D$2:$D$200),0)) -> 13 | J7: =H7-I7 -> 3 | K7: =E7*3+F7 -> 7
A8: 6 | B8: ITALIA | C8: 1 | D8: =SUMPRODUCT((Risultati!$C$2:$C$200=B8)*(Risultati!$D$2:$D$200<>""))+SUMPRODUCT((Risultati!$G$2:$G$200=B8)*(Risultati!$D$2:$D$200<>"")) -> 4 | E8: =SUMPRODUCT((Risultati!$C$2:$C$200=B8)*(IFERROR(VALUE(Risultati!$D$2:$D$200),0)>IFERROR(VALUE(Risultati!$F$2:$F$200),0)))+SUMPRODUCT((Risultati!$G$2:$G$200=B8)*(IFERROR(VALUE(Risultati!$F$2:$F$200),0)>IFERROR(VALUE(Risultati!$D$2:$D$200),0))) -> 2 | F8: =SUMPRODUCT((Risultati!$C$2:$C$200=B8)*(Risultati!$D$2:$D$200<>"")*((IFERROR(VALUE(Risultati!$D$2:$D$200),0))=(IFERROR(VALUE(Risultati!$F$2:$F$200),0))))+SUMPRODUCT((Risultati!$G$2:$G$200=B8)*(Risultati!$D$2:$D$200<>"")*((IFERROR(VALUE(Risultati!$D$2:$D$200),0))=(IFERROR(VALUE(Risultati!$F$2:$F$200),0)))) -> 2 | G8: =SUMPRODUCT((Risultati!$C$2:$C$200=B8)*(Risultati!$D$2:$D$200<>"")*((IFERROR(VALUE(Risultati!$D$2:$D$200),0))<(IFERROR(VALUE(Risultati!$F$2:$F$200),0))))+SUMPRODUCT((Risultati!$G$2:$G$200=B8)*(Risultati!$D$2:$D$200<>"")*((IFERROR(VALUE(Risultati!$F$2:$F$200),0))<(IFERROR(VALUE(Risultati!$D$2:$D$200),0)))) -> 0 | H8: =SUMPRODUCT((Risultati!$C$2:$C$200=B8)*(Risultati!$D$2:$D$200<>"")*IFERROR(VALUE(Risultati!$D$2:$D$200),0))+SUMPRODUCT((Risultati!$G$2:$G$200=B8)*(Risultati!$D$2:$D$200<>"")*IFERROR(VALUE(Risultati!$F$2:$F$200),0)) -> 22 | I8: =SUMPRODUCT((Risultati!$C$2:$C$200=B8)*(Risultati!$D$2:$D$200<>"")*IFERROR(VALUE(Risultati!$F$2:$F$200),0))+SUMPRODUCT((Risultati!$G$2:$G$200=B8)*(Risultati!$D$2:$D$200<>"")*IFERROR(VALUE(Risultati!$D$2:$D$200),0)) -> 10 | J8: =H8-I8 -> 12 | K8: =E8*3+F8 -> 8
A9: 7 | B9: URUGUAY | C9: 3 | D9: =SUMPRODUCT((Risultati!$C$2:$C$200=B9)*(Risultati!$D$2:$D$200<>""))+SUMPRODUCT((Risultati!$G$2:$G$200=B9)*(Risultati!$D$2:$D$200<>"")) -> 3 | E9: =SUMPRODUCT((Risultati!$C$2:$C$200=B9)*(IFERROR(VALUE(Risultati!$D$2:$D$200),0)>IFERROR(VALUE(Risultati!$F$2:$F$200),0)))+SUMPRODUCT((Risultati!$G$2:$G$200=B9)*(IFERROR(VALUE(Risultati!$F$2:$F$200),0)>IFERROR(VALUE(Risultati!$D$2:$D$200),0))) -> 0 | F9: =SUMPRODUCT((Risultati!$C$2:$C$200=B9)*(Risultati!$D$2:$D$200<>"")*((IFERROR(VALUE(Risultati!$D$2:$D$200),0))=(IFERROR(VALUE(Risultati!$F$2:$F$200),0))))+SUMPRODUCT((Risultati!$G$2:$G$200=B9)*(Risultati!$D$2:$D$200<>"")*((IFERROR(VALUE(Risultati!$D$2:$D$200),0))=(IFERROR(VALUE(Risultati!$F$2:$F$200),0)))) -> 0 | G9: =SUMPRODUCT((Risultati!$C$2:$C$200=B9)*(Risultati!$D$2:$D$200<>"")*((IFERROR(VALUE(Risultati!$D$2:$D$200),0))<(IFERROR(VALUE(Risultati!$F$2:$F$200),0))))+SUMPRODUCT((Risultati!$G$2:$G$200=B9)*(Risultati!$D$2:$D$200<>"")*((IFERROR(VALUE(Risultati!$F$2:$F$200),0))<(IFERROR(VALUE(Risultati!$D$2:$D$200),0)))) -> 3 | H9: =SUMPRODUCT((Risultati!$C$2:$C$200=B9)*(Risultati!$D$2:$D$200<>"")*IFERROR(VALUE(Risultati!$D$2:$D$200),0))+SUMPRODUCT((Risultati!$G$2:$G$200=B9)*(Risultati!$D$2:$D$200<>"")*IFERROR(VALUE(Risultati!$F$2:$F$200),0)) -> 5 | I9: =SUMPRODUCT((Risultati!$C$2:$C$200=B9)*(Risultati!$D$2:$D$200<>"")*IFERROR(VALUE(Risultati!$F$2:$F$200),0))+SUMPRODUCT((Risultati!$G$2:$G$200=B9)*(Risultati!$D$2:$D$200<>"")*IFERROR(VALUE(Risultati!$D$2:$D$200),0)) -> 23 | J9: =H9-I9 -> -18 | K9: =E9*3+F9 -> 0
A10: 8 | B10: MESSICO | C10: 3 | D10: =SUMPRODUCT((Risultati!$C$2:$C$200=B10)*(Risultati!$D$2:$D$200<>""))+SUMPRODUCT((Risultati!$G$2:$G$200=B10)*(Risultati!$D$2:$D$200<>"")) -> 4 | E10: =SUMPRODUCT((Risultati!$C$2:$C$200=B10)*(IFERROR(VALUE(Risultati!$D$2:$D$200),0)>IFERROR(VALUE(Risultati!$F$2:$F$200),0)))+SUMPRODUCT((Risultati!$G$2:$G$200=B10)*(IFERROR(VALUE(Risultati!$F$2:$F$200),0)>IFERROR(VALUE(Risultati!$D$2:$D$200),0))) -> 3 | F10: =SUMPRODUCT((Risultati!$C$2:$C$200=B10)*(Risultati!$D$2:$D$200<>"")*((IFERROR(VALUE(Risultati!$D$2:$D$200),0))=(IFERROR(VALUE(Risultati!$F$2:$F$200),0))))+SUMPRODUCT((Risultati!$G$2:$G$200=B10)*(Risultati!$D$2:$D$200<>"")*((IFERROR(VALUE(Risultati!$D$2:$D$200),0))=(IFERROR(VALUE(Risultati!$F$2:$F$200),0)))) -> 1 | G10: =SUMPRODUCT((Risultati!$C$2:$C$200=B10)*(Risultati!$D$2:$D$200<>"")*((IFERROR(VALUE(Risultati!$D$2:$D$200),0))<(IFERROR(VALUE(Risultati!$F$2:$F$200),0))))+SUMPRODUCT((Risultati!$G$2:$G$200=B10)*(Risultati!$D$2:$D$200<>"")*((IFERROR(VALUE(Risultati!$F$2:$F$200),0))<(IFERROR(VALUE(Risultati!$D$2:$D$200),0)))) -> 0 | H10: =SUMPRODUCT((Risultati!$C$2:$C$200=B10)*(Risultati!$D$2:$D$200<>"")*IFERROR(VALUE(Risultati!$D$2:$D$200),0))+SUMPRODUCT((Risultati!$G$2:$G$200=B10)*(Risultati!$D$2:$D$200<>"")*IFERROR(VALUE(Risultati!$F$2:$F$200),0)) -> 24 | I10: =SUMPRODUCT((Risultati!$C$2:$C$200=B10)*(Risultati!$D$2:$D$200<>"")*IFERROR(VALUE(Risultati!$F$2:$F$200),0))+SUMPRODUCT((Risultati!$G$2:$G$200=B10)*(Risultati!$D$2:$D$200<>"")*IFERROR(VALUE(Risultati!$D$2:$D$200),0)) -> 14 | J10: =H10-I10 -> 10 | K10: =E10*3+F10 -> 10
A11: 9 | B11: MAROCCO | C11: 1 | D11: =SUMPRODUCT((Risultati!$C$2:$C$200=B11)*(Risultati!$D$2:$D$200<>""))+SUMPRODUCT((Risultati!$G$2:$G$200=B11)*(Risultati!$D$2:$D$200<>"")) -> 3 | E11: =SUMPRODUCT((Risultati!$C$2:$C$200=B11)*(IFERROR(VALUE(Risultati!$D$2:$D$200),0)>IFERROR(VALUE(Risultati!$F$2:$F$200),0)))+SUMPRODUCT((Risultati!$G$2:$G$200=B11)*(IFERROR(VALUE(Risultati!$F$2:$F$200),0)>IFERROR(VALUE(Risultati!$D$2:$D$200),0))) -> 3 | F11: =SUMPRODUCT((Risultati!$C$2:$C$200=B11)*(Risultati!$D$2:$D$200<>"")*((IFERROR(VALUE(Risultati!$D$2:$D$200),0))=(IFERROR(VALUE(Risultati!$F$2:$F$200),0))))+SUMPRODUCT((Risultati!$G$2:$G$200=B11)*(Risultati!$D$2:$D$200<>"")*((IFERROR(VALUE(Risultati!$D$2:$D$200),0))=(IFERROR(VALUE(Risultati!$F$2:$F$200),0)))) -> 0 | G11: =SUMPRODUCT((Risultati!$C$2:$C$200=B11)*(Risultati!$D$2:$D$200<>"")*((IFERROR(VALUE(Risultati!$D$2:$D$200),0))<(IFERROR(VALUE(Risultati!$F$2:$F$200),0))))+SUMPRODUCT((Risultati!$G$2:$G$200=B11)*(Risultati!$D$2:$D$200<>"")*((IFERROR(VALUE(Risultati!$F$2:$F$200),0))<(IFERROR(VALUE(Risultati!$D$2:$D$200),0)))) -> 0 | H11: =SUMPRODUCT((Risultati!$C$2:$C$200=B11)*(Risultati!$D$2:$D$200<>"")*IFERROR(VALUE(Risultati!$D$2:$D$200),0))+SUMPRODUCT((Risultati!$G$2:$G$200=B11)*(Risultati!$D$2:$D$200<>"")*IFERROR(VALUE(Risultati!$F$2:$F$200),0)) -> 18 | I11: =SUMPRODUCT((Risultati!$C$2:$C$200=B11)*(Risultati!$D$2:$D$200<>"")*IFERROR(VALUE(Risultati!$F$2:$F$200),0))+SUMPRODUCT((Risultati!$G$2:$G$200=B11)*(Risultati!$D$2:$D$200<>"")*IFERROR(VALUE(Risultati!$D$2:$D$200),0)) -> 5 | J11: =H11-I11 -> 13 | K11: =E11*3+F11 -> 9
A12: 10 | B12: OLANDA | C12: 5 | D12: =SUMPRODUCT((Risultati!$C$2:$C$200=B12)*(Risultati!$D$2:$D$200<>""))+SUMPRODUCT((Risultati!$G$2:$G$200=B12)*(Risultati!$D$2:$D$200<>"")) -> 3 | E12: =SUMPRODUCT((Risultati!$C$2:$C$200=B12)*(IFERROR(VALUE(Risultati!$D$2:$D$200),0)>IFERROR(VALUE(Risultati!$F$2:$F$200),0)))+SUMPRODUCT((Risultati!$G$2:$G$200=B12)*(IFERROR(VALUE(Risultati!$F$2:$F$200),0)>IFERROR(VALUE(Risultati!$D$2:$D$200),0))) -> 2 | F12: =SUMPRODUCT((Risultati!$C$2:$C$200=B12)*(Risultati!$D$2:$D$200<>"")*((IFERROR(VALUE(Risultati!$D$2:$D$200),0))=(IFERROR(VALUE(Risultati!$F$2:$F$200),0))))+SUMPRODUCT((Risultati!$G$2:$G$200=B12)*(Risultati!$D$2:$D$200<>"")*((IFERROR(VALUE(Risultati!$D$2:$D$200),0))=(IFERROR(VALUE(Risultati!$F$2:$F$200),0)))) -> 1 | G12: =SUMPRODUCT((Risultati!$C$2:$C$200=B12)*(Risultati!$D$2:$D$200<>"")*((IFERROR(VALUE(Risultati!$D$2:$D$200),0))<(IFERROR(VALUE(Risultati!$F$2:$F$200),0))))+SUMPRODUCT((Risultati!$G$2:$G$200=B12)*(Risultati!$D$2:$D$200<>"")*((IFERROR(VALUE(Risultati!$F$2:$F$200),0))<(IFERROR(VALUE(Risultati!$D$2:$D$200),0)))) -> 0 | H12: =SUMPRODUCT((Risultati!$C$2:$C$200=B12)*(Risultati!$D$2:$D$200<>"")*IFERROR(VALUE(Risultati!$D$2:$D$200),0))+SUMPRODUCT((Risultati!$G$2:$G$200=B12)*(Risultati!$D$2:$D$200<>"")*IFERROR(VALUE(Risultati!$F$2:$F$200),0)) -> 20 | I12: =SUMPRODUCT((Risultati!$C$2:$C$200=B12)*(Risultati!$D$2:$D$200<>"")*IFERROR(VALUE(Risultati!$F$2:$F$200),0))+SUMPRODUCT((Risultati!$G$2:$G$200=B12)*(Risultati!$D$2:$D$200<>"")*IFERROR(VALUE(Risultati!$D$2:$D$200),0)) -> 7 | J12: =H12-I12 -> 13 | K12: =E12*3+F12 -> 7
A13: 11 | B13: INGHILTERRA | C13: 4 | D13: =SUMPRODUCT((Risultati!$C$2:$C$200=B13)*(Risultati!$D$2:$D$200<>""))+SUMPRODUCT((Risultati!$G$2:$G$200=B13)*(Risultati!$D$2:$D$200<>"")) -> 3 | E13: =SUMPRODUCT((Risultati!$C$2:$C$200=B13)*(IFERROR(VALUE(Risultati!$D$2:$D$200),0)>IFERROR(VALUE(Risultati!$F$2:$F$200),0)))+SUMPRODUCT((Risultati!$G$2:$G$200=B13)*(IFERROR(VALUE(Risultati!$F$2:$F$200),0)>IFERROR(VALUE(Risultati!$D$2:$D$200),0))) -> 1 | F13: =SUMPRODUCT((Risultati!$C$2:$C$200=B13)*(Risultati!$D$2:$D$200<>"")*((IFERROR(VALUE(Risultati!$D$2:$D$200),0))=(IFERROR(VALUE(Risultati!$F$2:$F$200),0))))+SUMPRODUCT((Risultati!$G$2:$G$200=B13)*(Risultati!$D$2:$D$200<>"")*((IFERROR(VALUE(Risultati!$D$2:$D$200),0))=(IFERROR(VALUE(Risultati!$F$2:$F$200),0)))) -> 0 | G13: =SUMPRODUCT((Risultati!$C$2:$C$200=B13)*(Risultati!$D$2:$D$200<>"")*((IFERROR(VALUE(Risultati!$D$2:$D$200),0))<(IFERROR(VALUE(Risultati!$F$2:$F$200),0))))+SUMPRODUCT((Risultati!$G$2:$G$200=B13)*(Risultati!$D$2:$D$200<>"")*((IFERROR(VALUE(Risultati!$F$2:$F$200),0))<(IFERROR(VALUE(Risultati!$D$2:$D$200),0)))) -> 2 | H13: =SUMPRODUCT((Risultati!$C$2:$C$200=B13)*(Risultati!$D$2:$D$200<>"")*IFERROR(VALUE(Risultati!$D$2:$D$200),0))+SUMPRODUCT((Risultati!$G$2:$G$200=B13)*(Risultati!$D$2:$D$200<>"")*IFERROR(VALUE(Risultati!$F$2:$F$200),0)) -> 8 | I13: =SUMPRODUCT((Risultati!$C$2:$C$200=B13)*(Risultati!$D$2:$D$200<>"")*IFERROR(VALUE(Risultati!$F$2:$F$200),0))+SUMPRODUCT((Risultati!$G$2:$G$200=B13)*(Risultati!$D$2:$D$200<>"")*IFERROR(VALUE(Risultati!$D$2:$D$200),0)) -> 12 | J13: =H13-I13 -> -4 | K13: =E13*3+F13 -> 3
A14: 12 | B14: JAMAICA | C14: 5 | D14: =SUMPRODUCT((Risultati!$C$2:$C$200=B14)*(Risultati!$D$2:$D$200<>""))+SUMPRODUCT((Risultati!$G$2:$G$200=B14)*(Risultati!$D$2:$D$200<>"")) -> 3 | E14: =SUMPRODUCT((Risultati!$C$2:$C$200=B14)*(IFERROR(VALUE(Risultati!$D$2:$D$200),0)>IFERROR(VALUE(Risultati!$F$2:$F$200),0)))+SUMPRODUCT((Risultati!$G$2:$G$200=B14)*(IFERROR(VALUE(Risultati!$F$2:$F$200),0)>IFERROR(VALUE(Risultati!$D$2:$D$200),0))) -> 0 | F14: =SUMPRODUCT((Risultati!$C$2:$C$200=B14)*(Risultati!$D$2:$D$200<>"")*((IFERROR(VALUE(Risultati!$D$2:$D$200),0))=(IFERROR(VALUE(Risultati!$F$2:$F$200),0))))+SUMPRODUCT((Risultati!$G$2:$G$200=B14)*(Risultati!$D$2:$D$200<>"")*((IFERROR(VALUE(Risultati!$D$2:$D$200),0))=(IFERROR(VALUE(Risultati!$F$2:$F$200),0)))) -> 0 | G14: =SUMPRODUCT((Risultati!$C$2:$C$200=B14)*(Risultati!$D$2:$D$200<>"")*((IFERROR(VALUE(Risultati!$D$2:$D$200),0))<(IFERROR(VALUE(Risultati!$F$2:$F$200),0))))+SUMPRODUCT((Risultati!$G$2:$G$200=B14)*(Risultati!$D$2:$D$200<>"")*((IFERROR(VALUE(Risultati!$F$2:$F$200),0))<(IFERROR(VALUE(Risultati!$D$2:$D$200),0)))) -> 3 | H14: =SUMPRODUCT((Risultati!$C$2:$C$200=B14)*(Risultati!$D$2:$D$200<>"")*IFERROR(VALUE(Risultati!$D$2:$D$200),0))+SUMPRODUCT((Risultati!$G$2:$G$200=B14)*(Risultati!$D$2:$D$200<>"")*IFERROR(VALUE(Risultati!$F$2:$F$200),0)) -> 3 | I14: =SUMPRODUCT((Risultati!$C$2:$C$200=B14)*(Risultati!$D$2:$D$200<>"")*IFERROR(VALUE(Risultati!$F$2:$F$200),0))+SUMPRODUCT((Risultati!$G$2:$G$200=B14)*(Risultati!$D$2:$D$200<>"")*IFERROR(VALUE(Risultati!$D$2:$D$200),0)) -> 15 | J14: =H14-I14 -> -12 | K14: =E14*3+F14 -> 0
... A26: 24 | B26: USA | C26: 2 | D26: =SUMPRODUCT((Risultati!$C$2:$C$200=B26)*(Risultati!$D$2:$D$200<>""))+SUMPRODUCT((Risultati!$G$2:$G$200=B26)*(Risultati!$D$2:$D$200<>"")) -> 3 | E26: =SUMPRODUCT((Risultati!$C$2:$C$200=B26)*(IFERROR(VALUE(Risultati!$D$2:$D$200),0)>IFERROR(VALUE(Risultati!$F$2:$F$200),0)))+SUMPRODUCT((Risultati!$G$2:$G$200=B26)*(IFERROR(VALUE(Risultati!$F$2:$F$200),0)>IFERROR(VALUE(Risultati!$D$2:$D$200),0))) -> 1 | F26: =SUMPRODUCT((Risultati!$C$2:$C$200=B26)*(Risultati!$D$2:$D$200<>"")*((IFERROR(VALUE(Risultati!$D$2:$D$200),0))=(IFERROR(VALUE(Risultati!$F$2:$F$200),0))))+SUMPRODUCT((Risultati!$G$2:$G$200=B26)*(Risultati!$D$2:$D$200<>"")*((IFERROR(VALUE(Risultati!$D$2:$D$200),0))=(IFERROR(VALUE(Risultati!$F$2:$F$200),0)))) -> 0 | G26: =SUMPRODUCT((Risultati!$C$2:$C$200=B26)*(Risultati!$D$2:$D$200<>"")*((IFERROR(VALUE(Risultati!$D$2:$D$200),0))<(IFERROR(VALUE(Risultati!$F$2:$F$200),0))))+SUMPRODUCT((Risultati!$G$2:$G$200=B26)*(Risultati!$D$2:$D$200<>"")*((IFERROR(VALUE(Risultati!$F$2:$F$200),0))<(IFERROR(VALUE(Risultati!$D$2:$D$200),0)))) -> 2 | H26: =SUMPRODUCT((Risultati!$C$2:$C$200=B26)*(Risultati!$D$2:$D$200<>"")*IFERROR(VALUE(Risultati!$D$2:$D$200),0))+SUMPRODUCT((Risultati!$G$2:$G$200=B26)*(Risultati!$D$2:$D$200<>"")*IFERROR(VALUE(Risultati!$F$2:$F$200),0)) -> 11 | I26: =SUMPRODUCT((Risultati!$C$2:$C$200=B26)*(Risultati!$D$2:$D$200<>"")*IFERROR(VALUE(Risultati!$F$2:$F$200),0))+SUMPRODUCT((Risultati!$G$2:$G$200=B26)*(Risultati!$D$2:$D$200<>"")*IFERROR(VALUE(Risultati!$D$2:$D$200),0)) -> 14 | J26: =H26-I26 -> -3 | K26: =E26*3+F26 -> 3

Sheet Marcatori
A1: 🥅 CLASSIFICA MARCATORI
A2: # | B2: NOME GIOCATORE | C2: NAZIONALE | D2: GOL
A3: 1 | B3: RIDA ECH CHOUBY | C3: MAROCCO | D3: 2
A4: 2 | B4: CRISTIAN FERRANTE | C4: MESSICO | D4: 3
A5: 3 | B5: ANDREA FERRANTE | C5: ECUADOR | D5: 3
A6: 4 | B6: SAMUELE OPRE | C6: MAROCCO | D6: 1
A7: 5 | B7: SIMONE ROMANI | C7: SVIZZERA | D7: 1
A8: 6 | B8: FEDERICO SABLONE | C8: MAROCCO | D8: 2
A9: 7 | B9: GABRIELE OLIVA | C9: BRASILE | D9: 1
A10: 8 | B10: TIZIANO PICCOLELLI | C10: BRASILE | D10: 1
A11: 9 | B11: GABRIELE MIZZONI | C11: BRASILE | D11: 1
A12: 10 | B12: ROBERT BANITA | C12: ARGENTINA | D12: 1
A13: 11 | B13: ALESSIO CENTOFANTE | C13: ARGENTINA | D13: 1
A14: 12 | B14: GABRIELE DI ROLLO | C14: ARGENTINA | D14: 1
... A18: 16 | B18: MIRCO FERRANTE | C18: MESSICO | D18: 1
A19: 17 | D19: 0
A20: 18 | D20: 0
A21: 19 | D21: 0
A22: 20 | D22: 0
A23: 21 | D23: 0
A24: 22 | D24: 0
A25: 23 | D25: 0
A26: 24 | D26: 0
A27: 25 | D27: 0
A28: 26 | D28: 0
A29: 27 | D29: 0
A30: 28 | D30: 0
... A32: 30 | D32: 0

Sheet Squadre
A1: 🏳️ NAZIONALI PARTECIPANTI — 24 SQUADRE
A2: # | B2: NAZIONALE | C2: FASCIA | D2: CONTINENTE | E2: LIVELLO
A3: 1 | B3: ARGENTINA | C3: 3 | D3: America | E3: ELITE
A4: 2 | B4: BRASILE | C4: 2 | D4: America | E4: ELITE
A5: 3 | B5: SPAGNA | C5: 2 | D5: Europa | E5: ELITE
A6: 4 | B6: GERMANIA | C6: 4 | D6: Europa | E6: ELITE
A7: 5 | B7: PORTOGALLO | C7: 2 | D7: Europa | E7: FORTI
A8: 6 | B8: ITALIA | C8: 1 | D8: Europa | E8: FORTI
A9: 7 | B9: URUGUAY | C9: 3 | D9: America | E9: FORTI
A10: 8 | B10: MESSICO | C10: 3 | D10: America | E10: FORTI
A11: 9 | B11: MAROCCO | C11: 1 | D11: Africa | E11: BUONE
A12: 10 | B12: OLANDA | C12: 5 | D12: Europa | E12: BUONE
A13: 11 | B13: INGHILTERRA | C13: 4 | D13: Europa | E13: BUONE
A14: 12 | B14: CROAZIA | C14: 5 | D14: Europa | E14: BUONE
... A26: 24 | B26: USA | C26: 2 | D26: America | E26: WILDCARD

Sheet Rose
A1: SQUADRA | B1: NOME | C1: RUOLO | D1: GOL
A2: MESSICO | B2: Steven D'Andrea | C2: PORTIERE
B3: Alessandro Rosati
B4: Emanuele D'Antoni | D4: 2
B5: Davide Di Cesare
B6: Christian Ferrante | D6: 3
B7: Eros Cerini
B8: Marco Mori
B9: Francesco Cheles
B10: Riccardo Cipolloni
B11: Leonardo Di Brango
B12: Tommaso De Propris
B13: Filippo Polinesi | C13: PORTIERE
B14: Federico Marcellitti
B15: Ousman Barry
B16: Nicolò Graziano | D16: 1
B17: Federico Bravetti | C17: PORTIERE
B18: Mirco Ferrante | D18: 1
A19: BRASILE | B19: Alessandro Colajanni | C19: PORTIERE
B20: Riccardo Attilia | C20: PORTIERE
B21: Leonardo Fratini
B22: Jacopo Petrucci
B23: Gabriele Oliva | D23: 1
B24: Dennys Savi
B25: Tiziano Piccolelli | D25: 1
B26: Gabriele Briatico
B27: Matteo Loreti
B28: Gabriele Mizzoni | D28: 1
B29: Valerio Condrò
B30: Samuele Tani
B31: Cristiano Cecchini
B32: Edoardo Piacentini
A33: URUGUAY | B33: Ludovico Zulli | C33: PORTIERE
B34: Mattia Bonansingo | C34: PORTIERE
B35: Damiano Ferreri | D35: 1
B36: Davide Moroni
B37: Valerio Greggi
B38: Marco Ferreri
B39: Federico Giusti
B40: Simone Marchini
...

Sheet Fase Finale
A1: 🏆 FASE FINALE — MONDIALE / COPPA D'ARGENTO / COPPA DI BRONZO
A2: FASE | B2: SQUADRA 1 | C2: GOL 1 | D2: SQUADRA 2 | E2: GOL 2 | F2: COMPETIZIONE
A3: Quarti di Finale | B3: TBD | D3: TBD | F3: 🌍 MONDIALE | G3: 46212
A4: Quarti di Finale | B4: TBD | D4: TBD | F4: 🌍 MONDIALE | G4: 46213
A5: Quarti di Finale | B5: TBD | D5: TBD | F5: 🌍 MONDIALE | G5: 46213
A6: Quarti di Finale | B6: TBD | D6: TBD | F6: 🌍 MONDIALE | G6: 46213
A7: Semifinali | B7: TBD | D7: TBD | F7: 🌍 MONDIALE | G7: 46216
A8: Semifinali | B8: TBD | D8: TBD | F8: 🌍 MONDIALE | G8: 46217
A9: 3° Posto | B9: TBD | D9: TBD | F9: 🌍 MONDIALE | G9: 46220
A10: 🏆 FINALE MONDIALE | B10: TBD | D10: TBD | F10: 🌍 MONDIALE | G10: 46220
A11: Quarti di Finale | B11: TBD | D11: TBD | F11: 🥈 COPPA D'ARGENTO | G11: 46211
A12: Quarti di Finale | B12: TBD | D12: TBD | F12: 🥈 COPPA D'ARGENTO | G12: 46211
A13: Quarti di Finale | B13: TBD | D13: TBD | F13: 🥈 COPPA D'ARGENTO | G13: 46212
A14: Quarti di Finale | B14: TBD | D14: TBD | F14: 🥈 COPPA D'ARGENTO | G14: 46212
... A24: 🥉 FINALE BRONZO | B24: TBD | D24: TBD | F24: 🥉 COPPA DI BRONZO | G24: 46220

Sheet GolPartite
A1: GG | B1: CASA | C1: TRASFERTA | D1: GIOCATORE | E1: SQUADRA | F1: GOL
A2: 1 | B2: MAROCCO | C2: SVIZZERA | D2: Samuele Opre | E2: MAROCCO | F2: 1
A3: 1 | B3: MAROCCO | C3: SVIZZERA | D3: Federico Sablone | E3: MAROCCO | F3: 2
A4: 1 | B4: MAROCCO | C4: SVIZZERA | D4: Rida Ech Chouby | E4: MAROCCO | F4: 2
A5: 1 | B5: MAROCCO | C5: SVIZZERA | D5: Simone Romani | E5: SVIZZERA | F5: 1
A6: 1 | B6: MAROCCO | C6: SVIZZERA
A7: 1 | B7: MAROCCO | C7: SVIZZERA
A8: 1 | B8: MAROCCO | C8: SVIZZERA
A9: 1 | B9: MAROCCO | C9: SVIZZERA
A10: 1 | B10: MAROCCO | C10: SVIZZERA
A11: 1 | B11: MAROCCO | C11: SVIZZERA
A12: 1 | B12: BRASILE | C12: ARGENTINA | D12: Gabriele Oliva | E12: BRASILE | F12: 1
A13: 1 | B13: BRASILE | C13: ARGENTINA | D13: Tiziano Piccolelli | E13: BRASILE | F13: 1
A14: 1 | B14: BRASILE | C14: ARGENTINA | D14: Gabriele Mizzoni | E14: BRASILE | F14: 1
A15: 1 | B15: BRASILE | C15: ARGENTINA | D15: Robert Banita | E15: ARGENTINA | F15: 1
A16: 1 | B16: BRASILE | C16: ARGENTINA | D16: Alessio Centofante | E16: ARGENTINA | F16: 1
A17: 1 | B17: BRASILE | C17: ARGENTINA | D17: Gabriele Di Rollo | E17: ARGENTINA | F17: 1
A18: 1 | B18: BRASILE | C18: ARGENTINA
A19: 1 | B19: BRASILE | C19: ARGENTINA
A20: 1 | B20: BRASILE | C20: ARGENTINA
A21: 1 | B21: BRASILE | C21: ARGENTINA
A22: 1 | B22: ECUADOR | C22: MESSICO | D22: Pietro Petrangeli | E22: ECUADOR | F22: 1
A23: 1 | B23: ECUADOR | C23: MESSICO | D23: Andrea Ferrante | E23: ECUADOR | F23: 3
A24: 1 | B24: ECUADOR | C24: MESSICO | D24: Emanuele D'Antoni | E24: MESSICO | F24: 2
A25: 1 | B25: ECUADOR | C25: MESSICO | D25: Christian Ferrante | E25: MESSICO | F25: 3
A26: 1 | B26: ECUADOR | C26: MESSICO | D26: Nicolò Graziano | E26: MESSICO | F26: 1
A27: 1 | B27: ECUADOR | C27: MESSICO | D27: Mirco Ferrante | E27: MESSICO | F27: 1
A28: 1 | B28: ECUADOR | C28: MESSICO
A29: 1 | B29: ECUADOR | C29: MESSICO
A30: 1 | B30: ECUADOR | C30: MESSICO
A31: 1 | B31: ECUADOR | C31: MESSICO
A32: 1 | B32: SPAGNA | C32: GERMANIA | D32: Gianluigi Valdastri | E32: SPAGNA | F32: 2
A33: 1 | B33: SPAGNA | C33: GERMANIA | D33: Federico Giulitti | E33: SPAGNA | F33: 2
A34: 1 | B34: SPAGNA | C34: GERMANIA | D34: Daniele Scancella | E34: SPAGNA | F34: 1
A35: 1 | B35: SPAGNA | C35: GERMANIA | D35: Carlo Alberto Rozzi | E35: GERMANIA | F35: 2
A36: 1 | B36: SPAGNA | C36: GERMANIA | D36: Damiano Fratini | E36: GERMANIA | F36: 2
A37: 1 | B37: SPAGNA | C37: GERMANIA | D37: Manuel Solitari | E37: GERMANIA | F37: 1
A38: 1 | B38: SPAGNA | C38: GERMANIA
A39: 1 | B39: SPAGNA | C39: GERMANIA
A40: 1 | B40: SPAGNA | C40: GERMANIA
...

Sheet 📋 ISTRUZIONI
A1: MONDIALE ESTATE 2026 — GUIDA RAPIDA AL FILE
A3: STRUTTURA DEL TORNEO
A4: 24 nazionali | Girone unico | 5 partite a testa | 60 partite totali
A5: Top 8 → MONDIALE a eliminazione diretta
A6: Dal 9° al 16° → COPPA D'ARGENTO a eliminazione diretta
A7: Dal 17° al 24° → COPPA DI BRONZO a eliminazione diretta
A9: COME INSERIRE I RISULTATI (sheet Risultati)
A10: Colonna GOL (D): gol squadra di casa | Colonna GOL (F): gol trasferta
A11: Lascia vuoto se la partita non si è ancora giocata
A13: COME AGGIORNARE LA CLASSIFICA (sheet Classifica)
A14: Aggiorna G, V, N, P, GF, GS, DR, PTS manualmente dopo ogni giornata
A15: Ordina per PTS decrescente e, a pari punti, per DR decrescente
... A31: Giornata 5: 13 Giugno 2026 | Fase Finale: da decidere
